Loaded dependency [python3/3.12.2]: sqlite3/3.45.1
Loaded dependency [python3/3.12.2]: gcc/12.3.0-binutils-2.40
Loaded module: python3/3.12.2

Loading python3/3.12.2
  Loading requirement: sqlite3/3.45.1 gcc/12.3.0-binutils-2.40
terminate called without an active exception
Process Process-5:
Traceback (most recent call last):
  File "/appl9/python/3.12.2/lib/python3.12/multiprocessing/process.py", line 314, in _bootstrap
    self.run()
  File "/appl9/python/3.12.2/lib/python3.12/multiprocessing/process.py", line 108, in run
    self._target(*self._args, **self._kwargs)
  File "/zhome/94/5/156250/Documents/FederatedLearning/FederatedLearning/HPC/cifar10_fedavg2.py", line 80, in gpu_process
    client_updates[client_id] = client_update(state_dict, device, dataloaders[client_id], epochs, stream)
                                ^^^^^^^^^^^^^^^^^^^^^^^^^^^^^^^^^^^^^^^^^^^^^^^^^^^^^^^^^^^^^^^^^^^^^^^^^
  File "/zhome/94/5/156250/Documents/FederatedLearning/FederatedLearning/HPC/cifar10_fedavg2.py", line 39, in client_update
    net = SmallCNN().to(device)
          ^^^^^^^^^^^^^^^^^^^^^
  File "/zhome/94/5/156250/Documents/FederatedLearning/.venv/lib/python3.12/site-packages/torch/nn/modules/module.py", line 1343, in to
    return self._apply(convert)
           ^^^^^^^^^^^^^^^^^^^^
  File "/zhome/94/5/156250/Documents/FederatedLearning/.venv/lib/python3.12/site-packages/torch/nn/modules/module.py", line 903, in _apply
    module._apply(fn)
  File "/zhome/94/5/156250/Documents/FederatedLearning/.venv/lib/python3.12/site-packages/torch/nn/modules/module.py", line 903, in _apply
    module._apply(fn)
  File "/zhome/94/5/156250/Documents/FederatedLearning/.venv/lib/python3.12/site-packages/torch/nn/modules/module.py", line 930, in _apply
    param_applied = fn(param)
                    ^^^^^^^^^
  File "/zhome/94/5/156250/Documents/FederatedLearning/.venv/lib/python3.12/site-packages/torch/nn/modules/module.py", line 1329, in convert
    return t.to(
           ^^^^^
RuntimeError: CUDA error: CUDA-capable device(s) is/are busy or unavailable
CUDA kernel errors might be asynchronously reported at some other API call, so the stacktrace below might be incorrect.
For debugging consider passing CUDA_LAUNCH_BLOCKING=1
Compile with `TORCH_USE_CUDA_DSA` to enable device-side assertions.

Traceback (most recent call last):
  File "/zhome/94/5/156250/Documents/FederatedLearning/FederatedLearning/HPC/cifar10_fedavg2.py", line 198, in <module>
    client_updates.extend(return_dict[i].values())
                          ~~~~~~~~~~~^^^
  File "<string>", line 2, in __getitem__
  File "/appl9/python/3.12.2/lib/python3.12/multiprocessing/managers.py", line 836, in _callmethod
    raise convert_to_error(kind, result)
KeyError: 0
